# 2022-12-23

Rust 将错误分为两大类:可恢复的(recoverable)和 不可恢复的(unrecoverable)错误。对于一个可恢复的错误，比如文件未找到的错误，我们很可能只想向用户报告问题并重试操作。不可恢复的错误总是 bug 出现的征兆，比如试图访问一个超过数组末端的位置，因此我们要立即停止程序。

大多数语言并不区分这两种错误，并采用类似异常这样方式统一处理他们。Rust 没有异常。相反，它有Result<T, E> 类型，用于处理可恢复的错误，还有 panic! 宏，在程序遇到不可恢复的错误时停止执行。

---

当出现 panic 时，程序默认会开始 展开(unwinding)，这意味着 Rust 会回溯栈并清理它遇到的每一个函数的数据，不过这个回溯并清理的过程有很多工作。另一种选择是直接 终止(abort)，这会不清理数据就退出程序。那么程序所使用的内存需要由操作系统来清理。如果你需要项目的最终二进制文件越小越好，panic 时通过在 Cargo.toml 的 [ profile ] 部分增加 panic = ’ abort’，可以由展开切换为终止。例如，如果你想要在 release 模式中 panic 时直接终止:

```toml
[profile.release]
panic = 'abort'
```

---

另一类错误叫做可恢复错误, 比如枚举 `Result`的处理:

```rust
fn main() {
  use std::fs::File;
  let f : Result<File, std::io::Error> = File::open("test.txt");
  let f = match f {
    Ok(file) => file,
    Err(e) => panic!("Cannot open file test.txt: {e:?}")
  };
}
```

`File::open` 函数的返回值类型是 `Result<File, std::io::Error>`。

`Result<T, E>`中, `T` 和 `E` 是泛型类型参数, `T` 代表成功时返回的 `Ok` 成员中的数据的类型，而 `E` 代表失败时返回的 `Err` 成员中的错误的类型。

注意与 `Option` 枚举一样，`Result` 枚举和其成员也被导入到了 `prelude` 中，所以就不需要在 `match` 分支中的 `Ok` 和 `Err` 之前指定 `Result::`。

---

在使用 `File::open`时, 可能希望根据不同的错误类型来采取不同的策略, 比如在文件不存在时创建文件, 而在其它错误时直接panic。此时可以采取以下写法:

```rust
use std::fs::File;
use std::io::ErrorKind;
fn main() {
    let f = File::open("hello.txt");
    let f = match f {
        Ok(file) => file,
        Err(error) => match error.kind() {
            ErrorKind::NotFound => match File::create("hello.txt") {
                Ok(fc) => fc,
                Err(e) => panic!("Problem creating the file: {:?}", e),
            },
            other_error => {
                panic!("Problem opening the file: {:?}", other_error)
            }
        },
    };
}
```

也可以采用如下写法(看不懂):

```rust
use std::fs::File;
use std::io::ErrorKind;
fn main() {
    let f = File::open("hello.txt").unwrap_or_else(|error| {
        if error.kind() == ErrorKind::NotFound {
            File::create("hello.txt").unwrap_or_else(|error| {
                panic!("Problem creating the file: {:?}", error);
            })
        } else {
            panic!("Problem opening the file: {:?}", error);
        }
    });
}
```

---

match 能够胜任它的工作，不过它可能有点冗长并且不总是能很好的表明其意图。Result<T, E> 类型定义了很多辅助方法来处理各种情况。其中之一叫做 unwrap，如果 Result 值是成员 Ok，unwrap 会返回 Ok 中的值。如果 Result 是成员 Err，unwrap 会为我们调用 panic!。这里是一个实践 unwrap 的例子:

```rust
use std::fs::File;
fn main() {
    let f = File::open("hello.txt").unwrap();
}
```

如果 `hello.txt`不存在, 就会panic:

```plaintext
thread 'main' panicked at 'called `Result::unwrap()` on an `Err` value: Os { code: 2, kind: NotFound, message: "No such file or directory" }', src/main.rs:5:37
note: run with `RUST_BACKTRACE=1` environment variable to display a backtrace
```

还有另一个类似于 unwrap 的方法它还允许我们选择 panic! 的错误信息:expect。使用 expect 而不是unwrap 并提供一个好的错误信息可以表明你的意图并更易于追踪 panic 的根源。expect 的语法看起来像这样:

```rust
use std::fs::File;
fn main() {
    let f = File::open("hello.txt").expect("It cannot be open!");
}

```

---

在编写自己的函数时, 向调用方返回 `Result<T, E>`也是一种较好的惯例:

```rust
use std::fs::File;
use std::io::{self, Read};
fn read_username_from_file() -> Result<String, io::Error> {
    let f = File::open("hello.txt");
    let mut f = match f {
        Ok(file) => file,
        Err(e) => return Err(e),
    };
    let mut s = String::new();
    match f.read_to_string(&mut s) {
        Ok(_) => Ok(s),
        Err(e) => Err(e),
    }
}
```

上例中, 函数调用了 `File::open`和 `read_to_string`。这2个函数也会返回 `Result<T, E>`。在这2个 `Result`的结果为 `Err`时, 函数没有自行处理, 而是将它们返回给了调用方, 由调用方负责解决。这种逻辑在rust被称作**传播(propogating)错误**。

---

传播错误可以使用 `?`运算符来简写。比如上例中的函数可以写成这样:

```rust
use std::fs::File;
use std::io;
use std::io::Read;
fn read_username_from_file() -> Result<String, io::Error> {
    let mut f = File::open("hello.txt")?;
    let mut s = String::new();
    f.read_to_string(&mut s)?; // 注意这里
    Ok(s) // 注意这里
}
```

Result 值之后的 `?` 被定义为与上上例中定义的处理 Result 值的 match 表达式有着类似的工作方式。如果 Result 的值是 Ok，这个表达式将会返回 Ok 中的值而程序将继续执行。如果值是 Err，Err 中的值将作为整个函数的返回值，就好像使用了 return 关键字一样，这样错误值就被传播给了调用者。

match 表达式与问号运算符所做的有一点不同:`?` 运算符所使用的错误值被传递给 `from` 函数，它定义于标准库的 `From trait` 中，其用来将错误从一种类型转换为另一种类型。当 `?` 运算符调用 `from` 函数时，收到的错误类型被转换为由当前函数返回类型所指定的错误类型。这在当函数返回单个错误类型来代表所有可能失败的方式时很有用，即使其可能会因很多种原因失败。只要每一个错误类型都实现了 from 函数来定义如何将自身转换为返回的错误类型，`?` 运算符会自动处理这些转换。

`File::open` 调用结尾的 `?` 将会把 `Ok` 中的值返回给变量 `f`。如果出现了错误，`?` 运算符会提早返回整个函数并将一些 `Err` 值传播给调用者。同理也适用于 `read_to_string` 调用结尾的 `?`。

上例代码甚至可以写成这样:

```rust
use std::fs::File;
use std::io;
use std::io::Read;
fn read_username_from_file() -> Result<String, io::Error> {
    let mut s = String::new();
    File::open("hello.txt")?.read_to_string(&mut s)?;
    Ok(s)
}
```

另外, `std::fs`也提供了直接接受文件名作为参数的 `read_to_string`, 因此也可以这样写:

```rust
use std::fs;
use std::io;
fn read_username_from_file() -> Result<String, io::Error> {
    fs::read_to_string("text.txt")
}
```

---

`?` 运算符只能被用于返回值与 `?` 作用的值相兼容的函数。因为 `?` 运算符被定义为从函数中提早返回一个值，这与上方示例中的 `match` 表达式有着完全相同的工作方式。如果我们尝试在 `main`函数中直接使用 `?`, 就会报错:

```rust
use std::fs::File;
fn main() {
    let f = File::open("hello.txt")?;
}
```

```plaintext
$ cargo build
   Compiling hello_cargo v0.1.0 (/Users/user/projects/hello_cargo)
error[E0277]: the `?` operator can only be used in a function that returns `Result` or `Option` (or another type that implements `FromResidual`)
 --> src/main.rs:3:36
  |
2 | fn main() {
  | --------- this function should return `Result` or `Option` to accept `?`
3 |     let f = File::open("hello.txt")?;
  |                                    ^ cannot use the `?` operator in a function that returns `()`
  |
  = help: the trait `FromResidual<Result<Infallible, std::io::Error>>` is not implemented for `()`

For more information about this error, try `rustc --explain E0277`.
error: could not compile `hello_cargo` due to previous error
```

这是因为这里 `main()`的返回值是 `()`, 而从报错信息中我们可以看出, 函数必须返回 `Result`或者 `Option`才能使用 `?`。

下面是一个在返回 `Option<T>`的函数中使用 `?`的例子:

```rust
fn last_char_of_first_line(text :&str) -> Option<char> {
  text.lines().next()?.chars().last()
}
```

这个函数返回 `Option<char>` 因为它可能会在这个位置找到一个字符，也可能没有字符。这段代码获取text 字符串 slice 作为参数并调用其 lines 方法，这会返回一个字符串中每一行的迭代器。因为函数希望检查第一行，所以调用了迭代器 next 来获取迭代器中第一个值。如果 text 是空字符串，next 调用会返回 None，此时我们可以使用 ? 来停止并从 last_char_of_first_line 返回 None。如果 text 不是空字符串，next 会返回一个包含 text 中第一行的字符串 slice 的 Some 值。

`?` 会提取这个字符串 slice，然后可以在字符串 slice 上调用 chars 来获取字符的迭代器。我们感兴趣的是第一行的最后一个字符，所以可以调用 last 来返回迭代器的最后一项。这是一个 Option，因为有可能第一行是一个空字符串，例如 text 以一个空行开头而后面的行有文本，像是 ”\nhi”。不过，如果第一行有最后一个字符，它会返回在一个 Some 成员中。? 运算符作用于其中给了我们一个简洁的表达这种逻辑的方式。如果我们不能在 Option 上使用 ? 运算符，则不得不使用更多的方法用或者 match 表达式来实现这些逻辑。

另外, 事实上, `main`也可以不返回 `()`。下面这段代码可以编译:

```rust
use std::error::Error;
use std::fs::File;
fn main() -> Result<(), Box<dyn Error>> {
    let f = File::open("hello.txt")?;
    Ok(())
}

```

`Box<dyn Error>` 类型是一个 trait 对象(trait object)(不懂)。目前可以将 `Box<dyn Error>` 理解为 ” 任何类型的错误”。在返回 Box `<dyn Error>` 错误类型 main 函数中对 Result 使用 ? 是允许的，因为它允许任何 Err 值提前返回。

当 main 函数返回 `Result<(), E>`，如果 main 返回 `Ok(())` 可执行程序会以 0 值退出，而如果 `main` 返回 `Err` 值则会以非零值退出;成功退出的程序会返回整数 0，运行错误的程序会返回非 0 的整数。Rust 也会从二进制程序中返回与这个惯例相兼容的整数。

---

The book:

> `main` 函数也可以返回任何实现了 `std::process::Termination trait` 的类型。截至本书编写时，Termination trait 是一个不稳定功能(unstable feature)，只能用于 Nightly Rust 中，所以你不能在稳定版 Rust (Stable Rust)中用自己的类型去实现，不过有朝一日应该可以!

---
